<?xml version="1.0"?>
<robot name="fusionbot" xmlns:xacro="http://www.ros.org/wiki/xacro">

  <xacro:include filename="$(find fusionbot_description)/urdf/materials.xacro" />
  <xacro:include filename="$(find fusionbot_description)/urdf/fusionbot_rtab.gazebo" />

  <link name='base_footprint' />

  <link name="base_link">
    <inertial>
      <origin rpy="0 0 0" xyz="0.0037594591254762827 0.0 0.052804115668456025" />
      <mass value="2.3079643337726483" />
      <inertia ixx="0.00789" ixy="0.0" ixz="-0.000325" iyy="0.008347" iyz="0.0" izz="0.01475" />
    </inertial>
    <visual>
      <origin rpy="0 0 0" xyz="0 0 0" />
      <geometry>
        <mesh filename="$(find fusionbot_description)/meshes/base_link.stl" scale="0.001 0.001 0.001" />
      </geometry>
      <material name="silver" />
    </visual>
    <collision>
      <origin rpy="0 0 0" xyz="0 0 0" />
      <geometry>
        <mesh filename="$(find fusionbot_description)/meshes/base_link.stl" scale="0.001 0.001 0.001" />
      </geometry>
    </collision>
  </link>

  <link name="right_wheel">
    <inertial>
      <origin rpy="0 0 0" xyz="-5.790023100122029e-18 -0.012499999999999997 0.0" />
      <mass value="0.1826050729899067" />
      <inertia ixx="0.000124" ixy="-0.0" ixz="0.0" iyy="0.000228" iyz="0.0" izz="0.000124" />
    </inertial>
    <visual>
      <origin rpy="0 0 0" xyz="-0.0 0.1 -0.05" />
      <geometry>
        <mesh filename="$(find fusionbot_description)/meshes/right_wheel_1.stl" scale="0.001 0.001 0.001" />
      </geometry>
      <material name="silver" />
    </visual>
    <collision>
      <origin rpy="0 0 0" xyz="-0.0 0.1 -0.05" />
      <geometry>
        <mesh filename="$(find fusionbot_description)/meshes/right_wheel_1.stl" scale="0.001 0.001 0.001" />
      </geometry>
    </collision>
  </link>

  <link name="left_wheel">
    <inertial>
      <origin rpy="0 0 0" xyz="-5.790023100122029e-18 0.012499999999999997 0.0" />
      <mass value="0.1826050729899067" />
      <inertia ixx="0.000124" ixy="0.0" ixz="0.0" iyy="0.000228" iyz="-0.0" izz="0.000124" />
    </inertial>
    <visual>
      <origin rpy="0 0 0" xyz="-0.0 -0.1 -0.05" />
      <geometry>
        <mesh filename="$(find fusionbot_description)/meshes/left_wheel_1.stl" scale="0.001 0.001 0.001" />
      </geometry>
      <material name="silver" />
    </visual>
    <collision>
      <origin rpy="0 0 0" xyz="-0.0 -0.1 -0.05" />
      <geometry>
        <mesh filename="$(find fusionbot_description)/meshes/left_wheel_1.stl" scale="0.001 0.001 0.001" />
      </geometry>
    </collision>
  </link>

  <link name="imu_link">
    <inertial>
      <mass value="0.01"/>
      <inertia ixx="0.01" ixy="0" ixz="0" iyy="0.01" iyz="0" izz="0.01"/>
    </inertial>
  </link>

  <xacro:include filename="$(find chess_world)/urdf/sensors/_d415.urdf.xacro"/>
  <xacro:include filename="$(find chess_world)/urdf/sensors/cam_holder.urdf.xacro"/>
  
  <xacro:sensor_d415 name="rgbd_camera" parent="base_link" flag_color="1" flag_ir="0" flag_depth="1" updaterate="20">
    <origin xyz="0.0 0.0 0.4" rpy="0.0 0.161379 0.0" /> 
  </xacro:sensor_d415>

  <joint name='base_link_joint' type='fixed'>
    <origin rpy="0 0 0" xyz="0 0 0" />
    <parent link="base_footprint" />
    <child link="base_link" />
  </joint>

  <joint name="right_wheel_joint" type="continuous">
    <origin rpy="0 0 0" xyz="0.0 -0.1 0.05" />
    <parent link="base_link" />
    <child link="right_wheel" />
    <axis xyz="0.0 1.0 0.0" />
  </joint>

  <joint name="left_wheel_joint" type="continuous">
    <origin rpy="0 0 0" xyz="0.0 0.1 0.05" />
    <parent link="base_link" />
    <child link="left_wheel" />
    <axis xyz="0.0 1.0 0.0" />
  </joint>

  <joint name="imu_joint" type="fixed">
    <origin rpy="0 0 0" xyz="0.0 0.0 0.05" />
    <parent link="base_link" />
    <child link="imu_link" />
    <axis xyz="0.0 0.0 0.0" />
  </joint>

</robot>